Workbook

Sheet Financials
D2: PLNm | E2: 2013 | F2: 2014 | G2: 2015 | H2: 2016 | I2: 2017 | J2: 2018 | K2: 2019 | L2: 2020 | M2: 2021 | N2: 2022 | O2: 2023 | P2: 2024 | Q2: 2025 | R2: 2026 | S2: 2027 | U2: CAGR 2019-2024
B3: x
B6: Financials
C8: 1. SUMMARY FINANCIALS
D9: Revenue | E9: =+IF(E63=0,"",E63) | F9: =+IF(F63=0,"",F63) | G9: =+IF(G63=0,"",G63) | H9: =+IF(H63=0,"",H63) | I9: =+IF(I63=0,"",I63) | J9: =+IF(J63=0,"",J63) | K9: =+IF(K63=0,"",K63) | L9: =+IF(L63=0,"",L63) | ... S9: =+IF(S63=0,"",S63) | U9: =IFERROR((P9/K9)^(1/(P$2-K$2))-1,"")
D10: Growth (%) | E10: =+IFERROR(E9/D9-1,"") | F10: =+IFERROR(F9/E9-1,"") | G10: =+IFERROR(G9/F9-1,"") | H10: =+IFERROR(H9/G9-1,"") | I10: =+IFERROR(I9/H9-1,"") | J10: =+IFERROR(J9/I9-1,"") | K10: =+IFERROR(K9/J9-1,"") | L10: =+IFERROR(L9/K9-1,"") | ... S10: =+IFERROR(S9/R9-1,"")
D11: Gross margin | E11: =+IF(E67=E63,"",E67) | F11: =+IF(F67=F63,"",F67) | G11: =+IF(G67=G63,"",G67) | H11: =+IF(H67=H63,"",H67) | I11: =+IF(I67=I63,"",I67) | J11: =+IF(J67=J63,"",J67) | K11: =+IF(K67=K63,"",K67) | L11: =+IF(L67=L63,"",L67) | ... S11: =+IF(S67=S63,"",S67) | U11: =IFERROR((P11/K11)^(1/(P$2-K$2))-1,"")
D12: % of sales | E12: =+IFERROR(E11/E$9,"") | F12: =+IFERROR(F11/F$9,"") | G12: =+IFERROR(G11/G$9,"") | H12: =+IFERROR(H11/H$9,"") | I12: =+IFERROR(I11/I$9,"") | J12: =+IFERROR(J11/J$9,"") | K12: =+IFERROR(K11/K$9,"") | L12: =+IFERROR(L11/L$9,"") | ... S12: =+IFERROR(S11/S$9,"")
D13: Adjusted EBITDA | E13: =+IF(E107-E76=0,"",E107) | F13: =+IF(F107-F76=0,"",F107) | G13: =+IF(G107-G76=0,"",G107) | H13: =+IF(H107-H76=0,"",H107) | I13: =+IF(I107-I76=0,"",I107) | J13: =+IF(J107-J76=0,"",J107) | K13: =+IF(K107-K76=0,"",K107) | L13: =+IF(L107-L76=0,"",L107) | ... S13: =+IF(S107-S76=0,"",S107) | U13: =IFERROR((P13/K13)^(1/(P$2-K$2))-1,"")
D14: % of sales | E14: =+IFERROR(E13/E$9,"") | F14: =+IFERROR(F13/F$9,"") | G14: =+IFERROR(G13/G$9,"") | H14: =+IFERROR(H13/H$9,"") | I14: =+IFERROR(I13/I$9,"") | J14: =+IFERROR(J13/J$9,"") | K14: =+IFERROR(K13/K$9,"") | L14: =+IFERROR(L13/L$9,"") | ... S14: =+IFERROR(S13/S$9,"")
D15: EBITDA | E15: =+IF(E76=0,"",E76) | F15: =+IF(F76=0,"",F76) | G15: =+IF(G76=0,"",G76) | H15: =+IF(H76=0,"",H76) | I15: =+IF(I76=0,"",I76) | J15: =+IF(J76=0,"",J76) | K15: =+IF(K76=0,"",K76) | L15: =+IF(L76=0,"",L76) | ... S15: =+IF(S76=0,"",S76) | U15: =IFERROR((P15/K15)^(1/(P$2-K$2))-1,"")
D16: % of sales | E16: =+IFERROR(E15/E$9,"") | F16: =+IFERROR(F15/F$9,"") | G16: =+IFERROR(G15/G$9,"") | H16: =+IFERROR(H15/H$9,"") | I16: =+IFERROR(I15/I$9,"") | J16: =+IFERROR(J15/J$9,"") | K16: =+IFERROR(K15/K$9,"") | L16: =+IFERROR(L15/L$9,"") | ... S16: =+IFERROR(S15/S$9,"")
D17: Adjusted EBIT | E17: =+IF(E108-E69=0,"",E108) | F17: =+IF(F108-F69=0,"",F108) | G17: =+IF(G108-G69=0,"",G108) | H17: =+IF(H108-H69=0,"",H108) | I17: =+IF(I108-I69=0,"",I108) | J17: =+IF(J108-J69=0,"",J108) | K17: =+IF(K108-K69=0,"",K108) | L17: =+IF(L108-L69=0,"",L108) | ... S17: =+IF(S108-S69=0,"",S108) | U17: =IFERROR((P17/K17)^(1/(P$2-K$2))-1,"")
D18: % of sales | E18: =+IFERROR(E17/E$9,"") | F18: =+IFERROR(F17/F$9,"") | G18: =+IFERROR(G17/G$9,"") | H18: =+IFERROR(H17/H$9,"") | I18: =+IFERROR(I17/I$9,"") | J18: =+IFERROR(J17/J$9,"") | K18: =+IFERROR(K17/K$9,"") | L18: =+IFERROR(L17/L$9,"") | ... S18: =+IFERROR(S17/S$9,"")
D19: EBIT | E19: =+IF(E69=0,"",E69) | F19: =+IF(F69=0,"",F69) | G19: =+IF(G69=0,"",G69) | H19: =+IF(H69=0,"",H69) | I19: =+IF(I69=0,"",I69) | J19: =+IF(J69=0,"",J69) | K19: =+IF(K69=0,"",K69) | L19: =+IF(L69=0,"",L69) | ... S19: =+IF(S69=0,"",S69) | U19: =IFERROR((P19/K19)^(1/(P$2-K$2))-1,"")
D20: % of sales | E20: =+IFERROR(E19/E$9,"") | F20: =+IFERROR(F19/F$9,"") | G20: =+IFERROR(G19/G$9,"") | H20: =+IFERROR(H19/H$9,"") | I20: =+IFERROR(I19/I$9,"") | J20: =+IFERROR(J19/J$9,"") | K20: =+IFERROR(K19/K$9,"") | L20: =+IFERROR(L19/L$9,"") | ... S20: =+IFERROR(S19/S$9,"")
D21: Total assets | E21: =+IF(E80=0,"",E80) | F21: =+IF(F80=0,"",F80) | G21: =+IF(G80=0,"",G80) | H21: =+IF(H80=0,"",H80) | I21: =+IF(I80=0,"",I80) | J21: =+IF(J80=0,"",J80) | K21: =+IF(K80=0,"",K80) | L21: =+IF(L80=0,"",L80) | ... S21: =+IF(S80=0,"",S80)
D23: CAPEX | E23: =+IF(E93=0,"",E93) | F23: =+IF(F93=0,"",F93) | G23: =+IF(G93=0,"",G93) | H23: =+IF(H93=0,"",H93) | I23: =+IF(I93=0,"",I93) | J23: =+IF(J93=0,"",J93) | K23: =+IF(K93=0,"",K93) | L23: =+IF(L93=0,"",L93) | ... S23: =+IF(S93=0,"",S93)
D25: Interest-bearing debt | E25: =+IF(E87=0,"",E87) | F25: =+IF(F87=0,"",F87) | G25: =+IF(G87=0,"",G87) | H25: =+IF(H87=0,"",H87) | I25: =+IF(I87=0,"",I87) | J25: =+IF(J87=0,"",J87) | K25: =+IF(K87=0,"",K87) | L25: =+IF(L87=0,"",L87) | ... S25: =+IF(S87=0,"",S87)
D26: Cash & cash equivalents | E26: =+IF(E88=0,"",E88) | F26: =+IF(F88=0,"",F88) | G26: =+IF(G88=0,"",G88) | H26: =+IF(H88=0,"",H88) | I26: =+IF(I88=0,"",I88) | J26: =+IF(J88=0,"",J88) | K26: =+IF(K88=0,"",K88) | L26: =+IF(L88=0,"",L88) | ... S26: =+IF(S88=0,"",S88)
D27: Net debt | E27: =IF(SUM(E25)-SUM(E26)=0,"",SUM(E25)-SUM(E26)) | F27: =IF(SUM(F25)-SUM(F26)=0,"",SUM(F25)-SUM(F26)) | G27: =IF(SUM(G25)-SUM(G26)=0,"",SUM(G25)-SUM(G26)) | H27: =IF(SUM(H25)-SUM(H26)=0,"",SUM(H25)-SUM(H26)) | I27: =IF(SUM(I25)-SUM(I26)=0,"",SUM(I25)-SUM(I26)) | J27: =IF(SUM(J25)-SUM(J26)=0,"",SUM(J25)-SUM(J26)) | K27: =IF(SUM(K25)-SUM(K26)=0,"",SUM(K25)-SUM(K26)) | L27: =IF(SUM(L25)-SUM(L26)=0,"",SUM(L25)-SUM(L26)) | ... S27: =IF(SUM(S25)-SUM(S26)=0,"",SUM(S25)-SUM(S26))
D29: Inventory | E29: =+IF(E82=0,"",E82) | F29: =+IF(F82=0,"",F82) | G29: =+IF(G82=0,"",G82) | H29: =+IF(H82=0,"",H82) | I29: =+IF(I82=0,"",I82) | J29: =+IF(J82=0,"",J82) | K29: =+IF(K82=0,"",K82) | L29: =+IF(L82=0,"",L82) | ... S29: =+IF(S82=0,"",S82)
D30: Receivables | E30: =+IF(E83=0,"",E83) | F30: =+IF(F83=0,"",F83) | G30: =+IF(G83=0,"",G83) | H30: =+IF(H83=0,"",H83) | I30: =+IF(I83=0,"",I83) | J30: =+IF(J83=0,"",J83) | K30: =+IF(K83=0,"",K83) | L30: =+IF(L83=0,"",L83) | ... S30: =+IF(S83=0,"",S83)
D31: Payables | E31: =+IF(E84=0,"",E84) | F31: =+IF(F84=0,"",F84) | G31: =+IF(G84=0,"",G84) | H31: =+IF(H84=0,"",H84) | I31: =+IF(I84=0,"",I84) | J31: =+IF(J84=0,"",J84) | K31: =+IF(K84=0,"",K84) | L31: =+IF(L84=0,"",L84) | ... S31: =+IF(S84=0,"",S84)
D32: Trade working capital | E32: =IF(SUM(E29:E30)-SUM(E31)=0,"",SUM(E29:E30)-SUM(E31)) | F32: =IF(SUM(F29:F30)-SUM(F31)=0,"",SUM(F29:F30)-SUM(F31)) | G32: =IF(SUM(G29:G30)-SUM(G31)=0,"",SUM(G29:G30)-SUM(G31)) | H32: =IF(SUM(H29:H30)-SUM(H31)=0,"",SUM(H29:H30)-SUM(H31)) | I32: =IF(SUM(I29:I30)-SUM(I31)=0,"",SUM(I29:I30)-SUM(I31)) | J32: =IF(SUM(J29:J30)-SUM(J31)=0,"",SUM(J29:J30)-SUM(J31)) | K32: =IF(SUM(K29:K30)-SUM(K31)=0,"",SUM(K29:K30)-SUM(K31)) | L32: =IF(SUM(L29:L30)-SUM(L31)=0,"",SUM(L29:L30)-SUM(L31)) | ... S32: =IF(SUM(S29:S30)-SUM(S31)=0,"",SUM(S29:S30)-SUM(S31))
D34: FTEs | E34: =IF(E95=0,"",E95) | F34: =IF(F95=0,"",F95) | G34: =IF(G95=0,"",G95) | H34: =IF(H95=0,"",H95) | I34: =IF(I95=0,"",I95) | J34: =IF(J95=0,"",J95) | K34: =IF(K95=0,"",K95) | L34: =IF(L95=0,"",L95) | ... S34: =IF(S95=0,"",S95) | U34: =IFERROR((P34/K34)^(1/(P$2-K$2))-1,"")
D35: Growth (%) | F35: =IF(F34=0,"",IFERROR(F34/E34-1,"")) | G35: =IF(G34=0,"",IFERROR(G34/F34-1,"")) | H35: =IF(H34=0,"",IFERROR(H34/G34-1,"")) | I35: =IF(I34=0,"",IFERROR(I34/H34-1,"")) | J35: =IF(J34=0,"",IFERROR(J34/I34-1,"")) | K35: =IF(K34=0,"",IFERROR(K34/J34-1,"")) | L35: =IF(L34=0,"",IFERROR(L34/K34-1,"")) | M35: =IF(M34=0,"",IFERROR(M34/L34-1,"")) | ... S35: =IF(S34=0,"",IFERROR(S34/R34-1,""))
D37: Cash conversion - EBIT-based | E37: =IFERROR(IF(E17="",E19,E17)/IF(E13="",E15,E13),"") | F37: =IFERROR(IF(F17="",F19,F17)/IF(F13="",F15,F13),"") | G37: =IFERROR(IF(G17="",G19,G17)/IF(G13="",G15,G13),"") | H37: =IFERROR(IF(H17="",H19,H17)/IF(H13="",H15,H13),"") | I37: =IFERROR(IF(I17="",I19,I17)/IF(I13="",I15,I13),"") | J37: =IFERROR(IF(J17="",J19,J17)/IF(J13="",J15,J13),"") | K37: =IFERROR(IF(K17="",K19,K17)/IF(K13="",K15,K13),"") | L37: =IFERROR(IF(L17="",L19,L17)/IF(L13="",L15,L13),"") | ... S37: =IFERROR(IF(S17="",S19,S17)/IF(S13="",S15,S13),"")
D38: Cash conversion - Capex-based | E38: =IFERROR(1-E23/IF(E13="",E15,E13),"") | F38: =IFERROR(1-F23/IF(F13="",F15,F13),"") | G38: =IFERROR(1-G23/IF(G13="",G15,G13),"") | H38: =IFERROR(1-H23/IF(H13="",H15,H13),"") | I38: =IFERROR(1-I23/IF(I13="",I15,I13),"") | J38: =IFERROR(1-J23/IF(J13="",J15,J13),"") | K38: =IFERROR(1-K23/IF(K13="",K15,K13),"") | L38: =IFERROR(1-L23/IF(L13="",L15,L13),"") | ... S38: =IFERROR(1-S23/IF(S13="",S15,S13),"")
D39: Cash conversion - Capex & WC based | F39: =IF(AND(F23<>"",F32<>"",E32<>"")=TRUE,IFERROR((IF(F13="",F15,F13)<>"")*(1-(F23+F32-E32)/IF(F13="",F15,F13)),""),"") | G39: =IF(AND(G23<>"",G32<>"",F32<>"")=TRUE,IFERROR((IF(G13="",G15,G13)<>"")*(1-(G23+G32-F32)/IF(G13="",G15,G13)),""),"") | H39: =IF(AND(H23<>"",H32<>"",G32<>"")=TRUE,IFERROR((IF(H13="",H15,H13)<>"")*(1-(H23+H32-G32)/IF(H13="",H15,H13)),""),"") | I39: =IF(AND(I23<>"",I32<>"",H32<>"")=TRUE,IFERROR((IF(I13="",I15,I13)<>"")*(1-(I23+I32-H32)/IF(I13="",I15,I13)),""),"") | J39: =IF(AND(J23<>"",J32<>"",I32<>"")=TRUE,IFERROR((IF(J13="",J15,J13)<>"")*(1-(J23+J32-I32)/IF(J13="",J15,J13)),""),"") | K39: =IF(AND(K23<>"",K32<>"",J32<>"")=TRUE,IFERROR((IF(K13="",K15,K13)<>"")*(1-(K23+K32-J32)/IF(K13="",K15,K13)),""),"") | L39: =IF(AND(L23<>"",L32<>"",K32<>"")=TRUE,IFERROR((IF(L13="",L15,L13)<>"")*(1-(L23+L32-K32)/IF(L13="",L15,L13)),""),"") | M39: =IF(AND(M23<>"",M32<>"",L32<>"")=TRUE,IFERROR((IF(M13="",M15,M13)<>"")*(1-(M23+M32-L32)/IF(M13="",M15,M13)),""),"") | ... S39: =IF(AND(S23<>"",S32<>"",R32<>"")=TRUE,IFERROR((IF(S13="",S15,S13)<>"")*(1-(S23+S32-R32)/IF(S13="",S15,S13)),""),"")
C41: 2. CONFIDENCE LEVEL
D42: Revenue
D43: Gross margin
D44: Adjusted EBITDA
D45: EBITDA
D46: Adjusted EBIT
D47: EBIT
D48: Total assets
D49: CAPEX
D50: Interest-bearing debt
...

Sheet Segments
B2: Segmentations
B4: Segmentation of | G4: Segmentation of | L4: Segmentation of
B5: Segmentation by | G5: Segmentation by | L5: Segmentation by
C7: First year | D7: Last year | H7: First year | I7: Last year | M7: First year | N7: Last year
B8: =IF(C5=0,"",C5) | E8: CAGR | G8: =IF(H5=0,"",H5) | J8: CAGR | L8: =IF(M5=0,"",M5) | O8: CAGR
E9: =IFERROR((D9/C9)^(1/(D$8-C$8))-1,"") | J9: =IFERROR((I9/H9)^(1/(I$8-H$8))-1,"") | O9: =IFERROR((N9/M9)^(1/(N$8-M$8))-1,"")
E10: =IFERROR((D10/C10)^(1/(D$8-C$8))-1,"") | J10: =IFERROR((I10/H10)^(1/(I$8-H$8))-1,"") | O10: =IFERROR((N10/M10)^(1/(N$8-M$8))-1,"")
E11: =IFERROR((D11/C11)^(1/(D$8-C$8))-1,"") | J11: =IFERROR((I11/H11)^(1/(I$8-H$8))-1,"") | O11: =IFERROR((N11/M11)^(1/(N$8-M$8))-1,"")
E12: =IFERROR((D12/C12)^(1/(D$8-C$8))-1,"") | J12: =IFERROR((I12/H12)^(1/(I$8-H$8))-1,"") | O12: =IFERROR((N12/M12)^(1/(N$8-M$8))-1,"")
E13: =IFERROR((D13/C13)^(1/(D$8-C$8))-1,"") | J13: =IFERROR((I13/H13)^(1/(I$8-H$8))-1,"") | O13: =IFERROR((N13/M13)^(1/(N$8-M$8))-1,"")
E14: =IFERROR((D14/C14)^(1/(D$8-C$8))-1,"") | J14: =IFERROR((I14/H14)^(1/(I$8-H$8))-1,"") | O14: =IFERROR((N14/M14)^(1/(N$8-M$8))-1,"")
E15: =IFERROR((D15/C15)^(1/(D$8-C$8))-1,"") | J15: =IFERROR((I15/H15)^(1/(I$8-H$8))-1,"") | O15: =IFERROR((N15/M15)^(1/(N$8-M$8))-1,"")
E16: =IFERROR((D16/C16)^(1/(D$8-C$8))-1,"") | J16: =IFERROR((I16/H16)^(1/(I$8-H$8))-1,"") | O16: =IFERROR((N16/M16)^(1/(N$8-M$8))-1,"")
E17: =IFERROR((D17/C17)^(1/(D$8-C$8))-1,"") | J17: =IFERROR((I17/H17)^(1/(I$8-H$8))-1,"") | O17: =IFERROR((N17/M17)^(1/(N$8-M$8))-1,"")
E18: =IFERROR((D18/C18)^(1/(D$8-C$8))-1,"") | J18: =IFERROR((I18/H18)^(1/(I$8-H$8))-1,"") | O18: =IFERROR((N18/M18)^(1/(N$8-M$8))-1,"")
E19: =IFERROR((D19/C19)^(1/(D$8-C$8))-1,"") | J19: =IFERROR((I19/H19)^(1/(I$8-H$8))-1,"") | O19: =IFERROR((N19/M19)^(1/(N$8-M$8))-1,"")
E20: =IFERROR((D20/C20)^(1/(D$8-C$8))-1,"") | J20: =IFERROR((I20/H20)^(1/(I$8-H$8))-1,"") | O20: =IFERROR((N20/M20)^(1/(N$8-M$8))-1,"")
... E23: =IFERROR((D23/C23)^(1/(D$8-C$8))-1,"") | J23: =IFERROR((I23/H23)^(1/(I$8-H$8))-1,"") | O23: =IFERROR((N23/M23)^(1/(N$8-M$8))-1,"")
B25: Inputs and calculations

Sheet Footnotes
D2: =+X55 -> zł. | E2: =Financials!E2 -> 2013 | F2: =Financials!F2 -> 2014 | G2: =Financials!G2 -> 2015 | H2: =Financials!H2 -> 2016 | I2: =Financials!I2 -> 2017 | J2: =Financials!J2 -> 2018 | K2: =Financials!K2 -> 2019 | L2: =Financials!L2 -> 2020 | M2: 2021 | N2: 2022 | O2: 2023 | P2: 2024 | Q2: 2025 | R2: 2026 | S2: 2027
D3: =Financials!D100 -> Goodwill impairment | E3: =Financials!E100 -> 0 | F3: =Financials!F100 -> 0 | G3: =Financials!G100 -> 0 | H3: =Financials!H100 -> 0 | I3: =Financials!I100 -> 0 | J3: =Financials!J100 -> 0 | K3: =Financials!K100 -> 0 | ... S3: =Financials!S100 -> 0
D5: Year | E5: =+IF(E8=0,"",E$2) | F5: =+IF(F8=0,"",F$2) | G5: =+IF(G8=0,"",G$2) | H5: =+IF(H8=0,"",H$2) | I5: =+IF(I8=0,"",I$2) | J5: =+IF(J8=0,"",J$2) | K5: =+IF(K8=0,"",K$2) | L5: =+IF(L8=0,"",L$2) | ... S5: =+IF(S8=0,"",S$2)
D6: Min | E6: =+MIN(E5:S5) -> 0
D7: Max | E7: =+MAX(E5:S5) -> 0
D8: Test | E8: =IF(E3=0,0,1) -> 0 | F8: =IF(F3=0,0,1) -> 0 | G8: =IF(G3=0,0,1) -> 0 | H8: =IF(H3=0,0,1) -> 0 | I8: =IF(I3=0,0,1) -> 0 | J8: =IF(J3=0,0,1) -> 0 | K8: =IF(K3=0,0,1) -> 0 | L8: =IF(L3=0,0,1) -> 0 | ... S8: =IF(S3=0,0,1) -> 0
D9: Format | E9: =+IF(E8=0,"",IF(AND(E3<0.1,E3>-0.1),TEXT(E3*1000,"0"),TEXT(E3,"0.0"))) | F9: =+IF(F8=0,"",IF(AND(F3<0.1,F3>-0.1),TEXT(F3*1000,"0"),TEXT(F3,"0.0"))) | G9: =+IF(G8=0,"",IF(AND(G3<0.1,G3>-0.1),TEXT(G3*1000,"0"),TEXT(G3,"0.0"))) | H9: =+IF(H8=0,"",IF(AND(H3<0.1,H3>-0.1),TEXT(H3*1000,"0"),TEXT(H3,"0.0"))) | I9: =+IF(I8=0,"",IF(AND(I3<0.1,I3>-0.1),TEXT(I3*1000,"0"),TEXT(I3,"0.0"))) | J9: =+IF(J8=0,"",IF(AND(J3<0.1,J3>-0.1),TEXT(J3*1000,"0"),TEXT(J3,"0.0"))) | K9: =+IF(K8=0,"",IF(AND(K3<0.1,K3>-0.1),TEXT(K3*1000,"0"),TEXT(K3,"0.0"))) | L9: =+IF(L8=0,"",IF(AND(L3<0.1,L3>-0.1),TEXT(L3*1000,"0"),TEXT(L3,"0.0"))) | ... S9: =+IF(S8=0,"",IF(AND(S3<0.1,S3>-0.1),TEXT(S3*1000,"0"),TEXT(S3,"0.0")))
D10: Unit | E10: =+IF(E8=0,"",IF(AND(E3<0.1,E3>-0.1),"k","m")) | F10: =+IF(F8=0,"",IF(AND(F3<0.1,F3>-0.1),"k","m")) | G10: =+IF(G8=0,"",IF(AND(G3<0.1,G3>-0.1),"k","m")) | H10: =+IF(H8=0,"",IF(AND(H3<0.1,H3>-0.1),"k","m")) | I10: =+IF(I8=0,"",IF(AND(I3<0.1,I3>-0.1),"k","m")) | J10: =+IF(J8=0,"",IF(AND(J3<0.1,J3>-0.1),"k","m")) | K10: =+IF(K8=0,"",IF(AND(K3<0.1,K3>-0.1),"k","m")) | L10: =+IF(L8=0,"",IF(AND(L3<0.1,L3>-0.1),"k","m")) | ... S10: =+IF(S8=0,"",IF(AND(S3<0.1,S3>-0.1),"k","m"))
D11: Comma | E11: =IF(OR(E8=0,SUM($E8:$S8)<2),"",IF(SUM(E8:$S8)>1,", ","")) | F11: =IF(OR(F8=0,SUM($E8:$S8)<2),"",IF(SUM(F8:$S8)>1,", ","")) | G11: =IF(OR(G8=0,SUM($E8:$S8)<2),"",IF(SUM(G8:$S8)>1,", ","")) | H11: =IF(OR(H8=0,SUM($E8:$S8)<2),"",IF(SUM(H8:$S8)>1,", ","")) | I11: =IF(OR(I8=0,SUM($E8:$S8)<2),"",IF(SUM(I8:$S8)>1,", ","")) | J11: =IF(OR(J8=0,SUM($E8:$S8)<2),"",IF(SUM(J8:$S8)>1,", ","")) | K11: =IF(OR(K8=0,SUM($E8:$S8)<2),"",IF(SUM(K8:$S8)>1,", ","")) | L11: =IF(OR(L8=0,SUM($E8:$S8)<2),"",IF(SUM(L8:$S8)>1,", ","")) | ... S11: =IF(OR(S8=0,SUM($E8:$S8)<2),"",IF(SUM(S8:$S8)>1,", ",""))
D12: Text | E12: =+IF(E8=0,"",IF(SUM($E8:$S8)=1,$D$2&E9&E10,$D$2&E9&E10&" in "&E$2&E11)) | F12: =+IF(F8=0,"",IF(SUM($E8:$S8)=1,$D$2&F9&F10,$D$2&F9&F10&" in "&F$2&F11)) | G12: =+IF(G8=0,"",IF(SUM($E8:$S8)=1,$D$2&G9&G10,$D$2&G9&G10&" in "&G$2&G11)) | H12: =+IF(H8=0,"",IF(SUM($E8:$S8)=1,$D$2&H9&H10,$D$2&H9&H10&" in "&H$2&H11)) | I12: =+IF(I8=0,"",IF(SUM($E8:$S8)=1,$D$2&I9&I10,$D$2&I9&I10&" in "&I$2&I11)) | J12: =+IF(J8=0,"",IF(SUM($E8:$S8)=1,$D$2&J9&J10,$D$2&J9&J10&" in "&J$2&J11)) | K12: =+IF(K8=0,"",IF(SUM($E8:$S8)=1,$D$2&K9&K10,$D$2&K9&K10&" in "&K$2&K11)) | L12: =+IF(L8=0,"",IF(SUM($E8:$S8)=1,$D$2&L9&L10,$D$2&L9&L10&" in "&L$2&L11)) | ... S12: =+IF(S8=0,"",IF(SUM($E8:$S8)=1,$D$2&S9&S10,$D$2&S9&S10&" in "&S$2&S11))
B14: 1 | D14: =IF(SUM(E8:S8)=0,"",IF(SUM(E8:S8)=1,"FY"&E6&": EBIT adjusted for goodwill impairment of "&E12&F12&G12&H12&I12&J12&K12&L12&M12&N12&O12&P12&Q12&R12&S12,"FY"&E6&"-"&E7&": EBIT(DA) adjusted for goodwill impairment ("&E12&F12&G12&H12&I12&J12&K12&L12&M12&N12&O12&P12&Q12&R12&S12&")"))
D16: =Financials!D101 -> Goodwill amortisation | E16: =Financials!E101 -> 0 | F16: =Financials!F101 -> 0 | G16: =Financials!G101 -> 0 | H16: =Financials!H101 -> 0 | I16: =Financials!I101 -> 0 | J16: =Financials!J101 -> 0 | K16: =Financials!K101 -> 0 | ... O16: =Financials!O101 -> 0
D18: Year | E18: =+IF(E21=0,"",E$2) | F18: =+IF(F21=0,"",F$2) | G18: =+IF(G21=0,"",G$2) | H18: =+IF(H21=0,"",H$2) | I18: =+IF(I21=0,"",I$2) | J18: =+IF(J21=0,"",J$2) | K18: =+IF(K21=0,"",K$2) | L18: =+IF(L21=0,"",L$2) | ... O18: =+IF(O21=0,"",O$2)
D19: Min | E19: =+MIN(E18:S18) -> 0
D20: Max | E20: =+MAX(E18:S18) -> 0
D21: Test | E21: =IF(E16=0,0,1) -> 0 | F21: =IF(F16=0,0,1) -> 0 | G21: =IF(G16=0,0,1) -> 0 | H21: =IF(H16=0,0,1) -> 0 | I21: =IF(I16=0,0,1) -> 0 | J21: =IF(J16=0,0,1) -> 0 | K21: =IF(K16=0,0,1) -> 0 | L21: =IF(L16=0,0,1) -> 0 | ... S21: =IF(S16=0,0,1) -> 0
D22: Format | E22: =+IF(E21=0,"",IF(AND(E16<0.1,E16>-0.1),TEXT(E16*1000,"0"),TEXT(E16,"0.0"))) | F22: =+IF(F21=0,"",IF(AND(F16<0.1,F16>-0.1),TEXT(F16*1000,"0"),TEXT(F16,"0.0"))) | G22: =+IF(G21=0,"",IF(AND(G16<0.1,G16>-0.1),TEXT(G16*1000,"0"),TEXT(G16,"0.0"))) | H22: =+IF(H21=0,"",IF(AND(H16<0.1,H16>-0.1),TEXT(H16*1000,"0"),TEXT(H16,"0.0"))) | I22: =+IF(I21=0,"",IF(AND(I16<0.1,I16>-0.1),TEXT(I16*1000,"0"),TEXT(I16,"0.0"))) | J22: =+IF(J21=0,"",IF(AND(J16<0.1,J16>-0.1),TEXT(J16*1000,"0"),TEXT(J16,"0.0"))) | K22: =+IF(K21=0,"",IF(AND(K16<0.1,K16>-0.1),TEXT(K16*1000,"0"),TEXT(K16,"0.0"))) | L22: =+IF(L21=0,"",IF(AND(L16<0.1,L16>-0.1),TEXT(L16*1000,"0"),TEXT(L16,"0.0"))) | ... S22: =+IF(S21=0,"",IF(AND(S16<0.1,S16>-0.1),TEXT(S16*1000,"0"),TEXT(S16,"0.0")))
D23: Unit | E23: =+IF(E21=0,"",IF(AND(E16<0.1,E16>-0.1),"k","m")) | F23: =+IF(F21=0,"",IF(AND(F16<0.1,F16>-0.1),"k","m")) | G23: =+IF(G21=0,"",IF(AND(G16<0.1,G16>-0.1),"k","m")) | H23: =+IF(H21=0,"",IF(AND(H16<0.1,H16>-0.1),"k","m")) | I23: =+IF(I21=0,"",IF(AND(I16<0.1,I16>-0.1),"k","m")) | J23: =+IF(J21=0,"",IF(AND(J16<0.1,J16>-0.1),"k","m")) | K23: =+IF(K21=0,"",IF(AND(K16<0.1,K16>-0.1),"k","m")) | L23: =+IF(L21=0,"",IF(AND(L16<0.1,L16>-0.1),"k","m")) | ... S23: =+IF(S21=0,"",IF(AND(S16<0.1,S16>-0.1),"k","m"))
D24: Comma | E24: =IF(OR(E21=0,SUM($E21:$S21)<2),"",IF(SUM(E21:$S21)>1,", ","")) | F24: =IF(OR(F21=0,SUM($E21:$S21)<2),"",IF(SUM(F21:$S21)>1,", ","")) | G24: =IF(OR(G21=0,SUM($E21:$S21)<2),"",IF(SUM(G21:$S21)>1,", ","")) | H24: =IF(OR(H21=0,SUM($E21:$S21)<2),"",IF(SUM(H21:$S21)>1,", ","")) | I24: =IF(OR(I21=0,SUM($E21:$S21)<2),"",IF(SUM(I21:$S21)>1,", ","")) | J24: =IF(OR(J21=0,SUM($E21:$S21)<2),"",IF(SUM(J21:$S21)>1,", ","")) | K24: =IF(OR(K21=0,SUM($E21:$S21)<2),"",IF(SUM(K21:$S21)>1,", ","")) | L24: =IF(OR(L21=0,SUM($E21:$S21)<2),"",IF(SUM(L21:$S21)>1,", ","")) | ... S24: =IF(OR(S21=0,SUM($E21:$S21)<2),"",IF(SUM(S21:$S21)>1,", ",""))
D25: Text | E25: =+IF(E21=0,"",IF(SUM($E21:$S21)=1,$D$2&E22&E23,$D$2&E22&E23&" in "&E$2&E24)) | F25: =+IF(F21=0,"",IF(SUM($E21:$S21)=1,$D$2&F22&F23,$D$2&F22&F23&" in "&F$2&F24)) | G25: =+IF(G21=0,"",IF(SUM($E21:$S21)=1,$D$2&G22&G23,$D$2&G22&G23&" in "&G$2&G24)) | H25: =+IF(H21=0,"",IF(SUM($E21:$S21)=1,$D$2&H22&H23,$D$2&H22&H23&" in "&H$2&H24)) | I25: =+IF(I21=0,"",IF(SUM($E21:$S21)=1,$D$2&I22&I23,$D$2&I22&I23&" in "&I$2&I24)) | J25: =+IF(J21=0,"",IF(SUM($E21:$S21)=1,$D$2&J22&J23,$D$2&J22&J23&" in "&J$2&J24)) | K25: =+IF(K21=0,"",IF(SUM($E21:$S21)=1,$D$2&K22&K23,$D$2&K22&K23&" in "&K$2&K24)) | L25: =+IF(L21=0,"",IF(SUM($E21:$S21)=1,$D$2&L22&L23,$D$2&L22&L23&" in "&L$2&L24)) | ... S25: =+IF(S21=0,"",IF(SUM($E21:$S21)=1,$D$2&S22&S23,$D$2&S22&S23&" in "&S$2&S24))
B27: 2 | D27: =IF(SUM(E21:S21)=0,"",IF(SUM(E21:S21)=1,"FY"&MIN($E$18:$S$18)&": EBIT adjusted for goodwill amortisation of "&E25&F25&G25&H25&I25&J25&K25&L25&M25&N25&O25&P25&Q25&R25&S25,"FY"&MIN($E$18:$S$18)&"-"&MAX($E$18:$S$18)&": EBIT adjusted for goodwill amortisation ("&E25&F25&G25&H25&I25&J25&K25&L25&M25&N25&O25&P25&Q25&R25&S25&")"))
D29: =Financials!D102 -> Non-recurring income | E29: =Financials!E102 -> 0 | F29: =Financials!F102 -> 0 | G29: =Financials!G102 -> 0 | H29: =Financials!H102 -> 0 | I29: =Financials!I102 -> 0 | J29: =Financials!J102 -> 0 | K29: =Financials!K102 -> 0 | ... O29: =Financials!O102 -> 0
D31: Year | E31: =+IF(E34=0,"",E$2) | F31: =+IF(F34=0,"",F$2) | G31: =+IF(G34=0,"",G$2) | H31: =+IF(H34=0,"",H$2) | I31: =+IF(I34=0,"",I$2) | J31: =+IF(J34=0,"",J$2) | K31: =+IF(K34=0,"",K$2) | L31: =+IF(L34=0,"",L$2) | ... S31: =+IF(S34=0,"",S$2)
D32: Min | E32: =+MIN(E31:S31) -> 0
D33: Max | E33: =+MAX(E31:S31) -> 0
D34: Test | E34: =IF(E29=0,0,1) -> 0 | F34: =IF(F29=0,0,1) -> 0 | G34: =IF(G29=0,0,1) -> 0 | H34: =IF(H29=0,0,1) -> 0 | I34: =IF(I29=0,0,1) -> 0 | J34: =IF(J29=0,0,1) -> 0 | K34: =IF(K29=0,0,1) -> 0 | L34: =IF(L29=0,0,1) -> 0 | ... S34: =IF(S29=0,0,1) -> 0
D35: Format | E35: =+IF(E34=0,"",IF(AND(E29<0.1,E29>-0.1),TEXT(E29*1000,"0"),TEXT(E29,"0.0"))) | F35: =+IF(F34=0,"",IF(AND(F29<0.1,F29>-0.1),TEXT(F29*1000,"0"),TEXT(F29,"0.0"))) | G35: =+IF(G34=0,"",IF(AND(G29<0.1,G29>-0.1),TEXT(G29*1000,"0"),TEXT(G29,"0.0"))) | H35: =+IF(H34=0,"",IF(AND(H29<0.1,H29>-0.1),TEXT(H29*1000,"0"),TEXT(H29,"0.0"))) | I35: =+IF(I34=0,"",IF(AND(I29<0.1,I29>-0.1),TEXT(I29*1000,"0"),TEXT(I29,"0.0"))) | J35: =+IF(J34=0,"",IF(AND(J29<0.1,J29>-0.1),TEXT(J29*1000,"0"),TEXT(J29,"0.0"))) | K35: =+IF(K34=0,"",IF(AND(K29<0.1,K29>-0.1),TEXT(K29*1000,"0"),TEXT(K29,"0.0"))) | L35: =+IF(L34=0,"",IF(AND(L29<0.1,L29>-0.1),TEXT(L29*1000,"0"),TEXT(L29,"0.0"))) | ... S35: =+IF(S34=0,"",IF(AND(S29<0.1,S29>-0.1),TEXT(S29*1000,"0"),TEXT(S29,"0.0")))
D36: Unit | E36: =+IF(E34=0,"",IF(AND(E29<0.1,E29>-0.1),"k","m")) | F36: =+IF(F34=0,"",IF(AND(F29<0.1,F29>-0.1),"k","m")) | G36: =+IF(G34=0,"",IF(AND(G29<0.1,G29>-0.1),"k","m")) | H36: =+IF(H34=0,"",IF(AND(H29<0.1,H29>-0.1),"k","m")) | I36: =+IF(I34=0,"",IF(AND(I29<0.1,I29>-0.1),"k","m")) | J36: =+IF(J34=0,"",IF(AND(J29<0.1,J29>-0.1),"k","m")) | K36: =+IF(K34=0,"",IF(AND(K29<0.1,K29>-0.1),"k","m")) | L36: =+IF(L34=0,"",IF(AND(L29<0.1,L29>-0.1),"k","m")) | ... S36: =+IF(S34=0,"",IF(AND(S29<0.1,S29>-0.1),"k","m"))
D37: Comma | E37: =IF(OR(E34=0,SUM($E34:$S34)<2),"",IF(SUM(E34:$S34)>1,", ","")) | F37: =IF(OR(F34=0,SUM($E34:$S34)<2),"",IF(SUM(F34:$S34)>1,", ","")) | G37: =IF(OR(G34=0,SUM($E34:$S34)<2),"",IF(SUM(G34:$S34)>1,", ","")) | H37: =IF(OR(H34=0,SUM($E34:$S34)<2),"",IF(SUM(H34:$S34)>1,", ","")) | I37: =IF(OR(I34=0,SUM($E34:$S34)<2),"",IF(SUM(I34:$S34)>1,", ","")) | J37: =IF(OR(J34=0,SUM($E34:$S34)<2),"",IF(SUM(J34:$S34)>1,", ","")) | K37: =IF(OR(K34=0,SUM($E34:$S34)<2),"",IF(SUM(K34:$S34)>1,", ","")) | L37: =IF(OR(L34=0,SUM($E34:$S34)<2),"",IF(SUM(L34:$S34)>1,", ","")) | ... S37: =IF(OR(S34=0,SUM($E34:$S34)<2),"",IF(SUM(S34:$S34)>1,", ",""))
D38: Text | E38: =+IF(E34=0,"",IF(SUM($E34:$S34)=1,$D$2&E35&E36,$D$2&E35&E36&" in "&E$2&E37)) | F38: =+IF(F34=0,"",IF(SUM($E34:$S34)=1,$D$2&F35&F36,$D$2&F35&F36&" in "&F$2&F37)) | G38: =+IF(G34=0,"",IF(SUM($E34:$S34)=1,$D$2&G35&G36,$D$2&G35&G36&" in "&G$2&G37)) | H38: =+IF(H34=0,"",IF(SUM($E34:$S34)=1,$D$2&H35&H36,$D$2&H35&H36&" in "&H$2&H37)) | I38: =+IF(I34=0,"",IF(SUM($E34:$S34)=1,$D$2&I35&I36,$D$2&I35&I36&" in "&I$2&I37)) | J38: =+IF(J34=0,"",IF(SUM($E34:$S34)=1,$D$2&J35&J36,$D$2&J35&J36&" in "&J$2&J37)) | K38: =+IF(K34=0,"",IF(SUM($E34:$S34)=1,$D$2&K35&K36,$D$2&K35&K36&" in "&K$2&K37)) | L38: =+IF(L34=0,"",IF(SUM($E34:$S34)=1,$D$2&L35&L36,$D$2&L35&L36&" in "&L$2&L37)) | ... S38: =+IF(S34=0,"",IF(SUM($E34:$S34)=1,$D$2&S35&S36,$D$2&S35&S36&" in "&S$2&S37))
U39: Concept
B40: 3 | D40: =IF(SUM(E34:S34)=0,"",IF(SUM(E34:S34)=1,"FY"&E32&": EBIT(DA) adjusted for non-recurring income of "&E38&F38&G38&H38&I38&J38&K38&L38&M38&N38&O38&P38&Q38&R38&S38&" "&U40,"FY"&E32&"-"&E33&": EBIT(DA) adjusted for non-recurring income ("&E38&F38&G38&H38&I38&J38&K38&L38&M38&N38&O38&P38&Q38&R38&S38&") "&U40)) | U40: =+IF(U59<>"","relating to "&LOWER(U59),"")
D42: =Financials!D103 -> Non-recurring expenses | E42: =Financials!E103 -> 0 | F42: =Financials!F103 -> 0 | G42: =Financials!G103 -> 0 | H42: =Financials!H103 -> 0 | I42: =Financials!I103 -> 0 | J42: =Financials!J103 -> 0 | K42: =Financials!K103 -> 0 | ... O42: =Financials!O103 -> 0
D44: Year | E44: =+IF(E47=0,"",E$2) | F44: =+IF(F47=0,"",F$2) | G44: =+IF(G47=0,"",G$2) | H44: =+IF(H47=0,"",H$2) | I44: =+IF(I47=0,"",I$2) | J44: =+IF(J47=0,"",J$2) | K44: =+IF(K47=0,"",K$2) | L44: =+IF(L47=0,"",L$2) | ... S44: =+IF(S47=0,"",S$2)
D45: Min | E45: =+MIN(E44:S44) -> 0
D46: Max | E46: =+MAX(E44:S44) -> 0
D47: Test | E47: =IF(E42=0,0,1) -> 0 | F47: =IF(F42=0,0,1) -> 0 | G47: =IF(G42=0,0,1) -> 0 | H47: =IF(H42=0,0,1) -> 0 | I47: =IF(I42=0,0,1) -> 0 | J47: =IF(J42=0,0,1) -> 0 | K47: =IF(K42=0,0,1) -> 0 | L47: =IF(L42=0,0,1) -> 0 | ... S47: =IF(S42=0,0,1) -> 0
D48: Format | E48: =+IF(E47=0,"",IF(AND(E42<0.1,E42>-0.1),TEXT(E42*1000,"0"),TEXT(E42,"0.0"))) | F48: =+IF(F47=0,"",IF(AND(F42<0.1,F42>-0.1),TEXT(F42*1000,"0"),TEXT(F42,"0.0"))) | G48: =+IF(G47=0,"",IF(AND(G42<0.1,G42>-0.1),TEXT(G42*1000,"0"),TEXT(G42,"0.0"))) | H48: =+IF(H47=0,"",IF(AND(H42<0.1,H42>-0.1),TEXT(H42*1000,"0"),TEXT(H42,"0.0"))) | I48: =+IF(I47=0,"",IF(AND(I42<0.1,I42>-0.1),TEXT(I42*1000,"0"),TEXT(I42,"0.0"))) | J48: =+IF(J47=0,"",IF(AND(J42<0.1,J42>-0.1),TEXT(J42*1000,"0"),TEXT(J42,"0.0"))) | K48: =+IF(K47=0,"",IF(AND(K42<0.1,K42>-0.1),TEXT(K42*1000,"0"),TEXT(K42,"0.0"))) | L48: =+IF(L47=0,"",IF(AND(L42<0.1,L42>-0.1),TEXT(L42*1000,"0"),TEXT(L42,"0.0"))) | ... S48: =+IF(S47=0,"",IF(AND(S42<0.1,S42>-0.1),TEXT(S42*1000,"0"),TEXT(S42,"0.0")))
D49: Unit | E49: =+IF(E47=0,"",IF(AND(E42<0.1,E42>-0.1),"k","m")) | F49: =+IF(F47=0,"",IF(AND(F42<0.1,F42>-0.1),"k","m")) | G49: =+IF(G47=0,"",IF(AND(G42<0.1,G42>-0.1),"k","m")) | H49: =+IF(H47=0,"",IF(AND(H42<0.1,H42>-0.1),"k","m")) | I49: =+IF(I47=0,"",IF(AND(I42<0.1,I42>-0.1),"k","m")) | J49: =+IF(J47=0,"",IF(AND(J42<0.1,J42>-0.1),"k","m")) | K49: =+IF(K47=0,"",IF(AND(K42<0.1,K42>-0.1),"k","m")) | L49: =+IF(L47=0,"",IF(AND(L42<0.1,L42>-0.1),"k","m")) | ... S49: =+IF(S47=0,"",IF(AND(S42<0.1,S42>-0.1),"k","m"))
D50: Comma | E50: =IF(OR(E47=0,SUM($E47:$S47)<2),"",IF(SUM(E47:$S47)>1,", ","")) | F50: =IF(OR(F47=0,SUM($E47:$S47)<2),"",IF(SUM(F47:$S47)>1,", ","")) | G50: =IF(OR(G47=0,SUM($E47:$S47)<2),"",IF(SUM(G47:$S47)>1,", ","")) | H50: =IF(OR(H47=0,SUM($E47:$S47)<2),"",IF(SUM(H47:$S47)>1,", ","")) | I50: =IF(OR(I47=0,SUM($E47:$S47)<2),"",IF(SUM(I47:$S47)>1,", ","")) | J50: =IF(OR(J47=0,SUM($E47:$S47)<2),"",IF(SUM(J47:$S47)>1,", ","")) | K50: =IF(OR(K47=0,SUM($E47:$S47)<2),"",IF(SUM(K47:$S47)>1,", ","")) | L50: =IF(OR(L47=0,SUM($E47:$S47)<2),"",IF(SUM(L47:$S47)>1,", ","")) | ... S50: =IF(OR(S47=0,SUM($E47:$S47)<2),"",IF(SUM(S47:$S47)>1,", ",""))
...

Sheet Currencies
A1: name | B1: title | C1: to_eur
A2: EUR | B2: Euro | C2: 1
A3: USD | B3: United States Dollar | C3: 0.83
A4: GBP | B4: Great British Pound | C4: 1.1
A5: JPY | B5: Japanese yen | C5: 0.0079
A6: CAD | B6: Canadian dollar | C6: 0.64
A7: RMB | B7: Chinese renminbi | C7: 0.13
A8: SEK | B8: Swedish krona | C8: 0.098
A9: NZD | B9: New Zealand dollar | C9: 0.58
A10: CHF | B10: Swiss Franc | C10: 0.93
A11: AUD | B11: Australian Dollar | C11: 0.61
A12: DKK | B12: Danish Krone | C12: 0.13
A13: NOK | B13: Norwegian krone | C13: 0.094
... A22: UAH | B22: Ukrainian Hryvnia | C22: 0.029
A27: 53.127
A28: =A27/C4 -> 48.297273

Sheet Lists
A1: Currency | C1: Currency2 | E1: Confidence level
A2: EURm | C2: € | E2: Actual
A3: GBPm | C3: £ | E3: Estimate
A4: USDm | C4: $
A5: CHFm | C5: CHF
A6: JPYm | C6: ¥
A7: CADm | C7: $
A8: RMBm | C8: ¥
A9: SEKm | C9: kr
A10: NZDm | C10: $
A11: AUDm | C11: $
A12: DKKm | C12: Kr.
A13: PLNm | C13: zł.
A14: NOKm | C14: kr
A15: CZKm | C15: Kč
... A17: RONm | C17: lei

Sheet Version
A1: File format | B1: gain_pro_asset_excel_v2
